Workbook
Name \A: #REF!
Name \B: #REF!
Name \C: #REF!
Name \D: #REF!
Name \E: #REF!
Name \F: #REF!
Name \G: #REF!
Name \H: #REF!
Name \I: #REF!
Name \J: #REF!
Name \K: #REF!
Name \L: #REF!
Name \P: #REF!
Name \S: #REF!
Name __ap1: #REF!
Name __ar1: #REF!
Name __EEU2002: #REF!
Name __JV1: #REF!
Name __LA2002: #REF!
Name __m1: #REF!
Name __m10: #REF!
Name __m2: #REF!
Name __m3: #REF!
Name __m4: #REF!
Name __m5: #REF!
Name __m6: #REF!
Name __m7: #REF!
Name __m8: #REF!
Name __m9: #REF!
Name __ma2: #REF!
Name __ma3: #REF!
Name __ma4: #REF!
Name __NAT2002: #REF!
Name __pic1: OFFSET(#REF!,#REF!,0)
Name __pic10: OFFSET(#REF!,#REF!,0)
Name __pic11: OFFSET(#REF!,#REF!,0)
Name __pic2: OFFSET(#REF!,#REF!,0)
Name __pic3: OFFSET(#REF!,#REF!,0)
Name __pic4: OFFSET(#REF!,#REF!,0)
Name __pic5: OFFSET(#REF!,#REF!,0)
Name __pic6: OFFSET(#REF!,#REF!,0)
Name __pic7: OFFSET(#REF!,#REF!,0)
Name __pic8: OFFSET(#REF!,#REF!,0)
Name __pic9: OFFSET(#REF!,#REF!,0)
Name __ret1: #REF!
Name __ROA94: #REF!
Name __ROA95: #REF!
Name __ROA97: #REF!
Name __SPE1: #REF!
Name __SPE2: #REF!
Name __TYP1: #REF!
Name __TYP2: #REF!
Name _04_Amt: #REF!
Name _04_Date: #REF!
Name _04_Fee: #REF!
Name _04_Int: #REF!
Name _04_Mat: #REF!
Name _04_Pickup: #REF!
Name _04_Refi: #REF!
Name _05_Amt: #REF!

Sheet Cover
B17: =+Capital_Inputs!D7 -> Project X
B23: Debt Only Model

Sheet Debt_Model
A1: x | Y1: x
B2: =+Capital_Inputs!D7 -> Project X
B3: {=MID(CELL("filename",A1),FIND("]",CELL("filename",A1))+1,255)} -> Debt_Model
B4: £000's, unless stated otherwise
O5: =N5+1 -> 1 | P5: =O5+1 -> 2
B7: Forward Base Rate Curve
B8: Debt Model Case | E8: 0.0375 | F8: =+E8 -> 0.0375 | G8: =+F8 -> 0.0375 | H8: =+G8 -> 0.0375 | I8: =+H8 -> 0.0375 | J8: =+I8 -> 0.0375 | K8: =+J8 -> 0.0375 | L8: =+K8 -> 0.0375 | M8: =+L8 -> 0.0375 | ... X8: =+W8 -> 0.0375
B10: EBITDA Forecast | D10: =+Capital_Inputs!F28 -> 7250 | E10: =+((H10-D10)/4)+D10 -> 7467.5 | F10: =+((H10-D10)/4)+E10 -> 7685 | G10: =+((H10-D10)/4)+F10 -> 7902.5 | H10: =+D10*(1+Capital_Inputs!$F$38) -> 8120 | I10: =+((L10-H10)/4)+H10 -> 8363.6 | J10: =+((L10-H10)/4)+I10 -> 8607.2 | K10: =+((L10-H10)/4)+J10 -> 8850.8 | L10: =+H10*(1+Capital_Inputs!$F$38) -> 9094.4 | M10: =+((P10-L10)/4)+L10 -> 9367.232 | N10: =+((P10-L10)/4)+M10 -> 9640.064 | O10: =+((P10-L10)/4)+N10 -> 9912.896 | P10: =+L10*(1+Capital_Inputs!$F$38) -> 10185.728 | Q10: =+((T10-P10)/4)+P10 -> 10491.3 | R10: =+((T10-P10)/4)+Q10 -> 10796.872 | S10: =+((T10-P10)/4)+R10 -> 11102.444 | T10: =+P10*(1+Capital_Inputs!$F$38) -> 11408.015 | U10: =+((X10-T10)/4)+T10 -> 11750.256 | V10: =+((X10-T10)/4)+U10 -> 12092.496 | W10: =+((X10-T10)/4)+V10 -> 12434.737 | X10: =+T10*(1+Capital_Inputs!$F$38) -> 12776.977
B11: Month | D11: =+Capital_Inputs!F14 -> 46143 | E11: =IF(E12<=Capital_Inputs!$F$18,EOMONTH(D11,3),"") -> 46265 | F11: =IF(F12<=Capital_Inputs!$F$18,EOMONTH(E11,3),"") -> 46356 | G11: =IF(G12<=Capital_Inputs!$F$18,EOMONTH(F11,3),"") -> 46446 | H11: =IF(H12<=Capital_Inputs!$F$18,EOMONTH(G11,3),"") -> 46538 | I11: =IF(I12<=Capital_Inputs!$F$18,EOMONTH(H11,3),"") -> 46630 | J11: =IF(J12<=Capital_Inputs!$F$18,EOMONTH(I11,3),"") -> 46721 | K11: =IF(K12<=Capital_Inputs!$F$18,EOMONTH(J11,3),"") -> 46812 | L11: =IF(L12<=Capital_Inputs!$F$18,EOMONTH(K11,3),"") -> 46904 | ... X11: =IF(X12<=Capital_Inputs!$F$18,EOMONTH(W11,3),"") -> 47999
B12: Month number | D12: 0 | E12: =+D12+3 -> 3 | F12: =+E12+3 -> 6 | G12: =+F12+3 -> 9 | H12: =+G12+3 -> 12 | I12: =+H12+3 -> 15 | J12: =+I12+3 -> 18 | K12: =+J12+3 -> 21 | L12: =+K12+3 -> 24 | ... X12: =+W12+3 -> 60
B14: Returns Summary
B16: Westbrooke Net Investor IRR | C16: {=XIRR( _xlfn._xlws.FILTER(D16:X16,$D$11:$X$11<=Capital_Inputs!$F$19), _xlfn._xlws.FILTER(Debt_Model!$D$11:$X$11,Debt_Model!$D$11:$X$11<=Capital_Inputs!$F$19) )} -> 0.31972077 | D16: =+D133 -> -8540 | E16: =+E133 -> 403.125 | F16: =+F133 -> 538.125 | G16: =+G133 -> 538.125 | H16: =+H133 -> 403.125 | I16: =+I133 -> 531.04303 | J16: =+J133 -> 531.04303 | K16: =+K133 -> 531.04303 | ... X16: =+X133 -> 15074.984
B17: Westbrooke Net Investor MoM | C17: =+SUM(E17:X17)/-D17 -> 2.8535607 | D17: =+D16 -> -8540 | E17: =+E16 -> 403.125 | F17: =+F16 -> 538.125 | G17: =+G16 -> 538.125 | H17: =+H16 -> 403.125 | I17: =+I16 -> 531.04303 | J17: =+J16 -> 531.04303 | K17: =+K16 -> 531.04303 | ... X17: =+X16 -> 15074.984
B19: Debt Schedules
B21: Global Facility
B22: Opening Balance | D22: 0 | E22: =D29 -> 28000 | F22: =E29 -> 28000 | G22: =F29 -> 28000 | H22: =G29 -> 28000 | I22: =H29 -> 26583.607 | J22: =I29 -> 26583.607 | K22: =J29 -> 26583.607 | L22: =K29 -> 26583.607 | ... X22: =W29 -> 22334.426
B23: Advances | D23: =+D39+D54+D69 -> 28000 | E23: =+E39+E54+E69 -> 0 | F23: =+F39+F54+F69 -> 0 | G23: =+G39+G54+G69 -> 0 | H23: =+H39+H54+H69 -> 0 | I23: =+I39+I54+I69 -> 0 | J23: =+J39+J54+J69 -> 0 | K23: =+K39+K54+K69 -> 0 | ... X23: =+X39+X54+X69 -> 0
B24: Arranging Fee | C24: =+D24/D23 -> 0.03 | D24: =+D40+D55+D70 -> 840 | E24: =+E40+E55+E70 -> 0 | F24: =+F40+F55+F70 -> 0 | G24: =+G40+G55+G70 -> 0 | H24: =+H40+H55+H70 -> 0 | I24: =+I40+I55+I70 -> 0 | J24: =+J40+J55+J70 -> 0 | K24: =+K40+K55+K70 -> 0 | ... X24: =+X40+X55+X70 -> 0
B25: Interest Cash Paid | C25: =(AVERAGE(E25:X25)/AVERAGE(E22:X22)*4) -> 0.1362741 | E25: =+E41+E56+E71 -> 930 | F25: =+F41+F56+F71 -> 930 | G25: =+G41+G56+G71 -> 930 | H25: =+H41+H56+H71 -> 930 | I25: =+I41+I56+I71 -> 893.70492 | J25: =+J41+J56+J71 -> 893.70492 | K25: =+K41+K56+K71 -> 893.70492 | L25: =+L41+L56+L71 -> 893.70492 | ... X25: =+X41+X56+X71 -> 784.81967
B26: Interest PIK | C26: =AVERAGE(E26:X26)/AVERAGE(E22:X22)*4 -> 0 | E26: =+E57+E72+E42 -> 0 | F26: =+F57+F72+F42 -> 0 | G26: =+G57+G72+G42 -> 0 | H26: =+H57+H72+H42 -> 0 | I26: =+I57+I72+I42 -> 0 | J26: =+J57+J72+J42 -> 0 | K26: =+K57+K72+K42 -> 0 | L26: =+L57+L72+L42 -> 0 | ... X26: =+X57+X72+X42 -> 0
B27: Amortisation | C27: =-AVERAGE(E27:X27)/AVERAGE(E22:X22)*4 -> 0.22511725 | H27: =+SUM(H43:H44,H58:H59,H73:H74) -> -1416.3934 | L27: =+SUM(L43:L44,L58:L59,L73:L74) -> -1416.3934 | P27: =+SUM(P43:P44,P58:P59,P73:P74) -> -1416.3934 | T27: =+SUM(T43:T44,T58:T59,T73:T74) -> -1416.3934 | X27: =+SUM(X43:X44,X58:X59,X73:X74) -> -1416.3934
B28: Repayments | E28: =IF(OR(E$12=Capital_Inputs!$F$18,E27<0),+E46+E61+E76,0) -> 0 | F28: =IF(OR(F$12=Capital_Inputs!$F$18,F27<0),+F46+F61+F76,0) -> 0 | G28: =IF(OR(G$12=Capital_Inputs!$F$18,G27<0),+G46+G61+G76,0) -> 0 | H28: =IF(OR(H$12=Capital_Inputs!$F$18,H27<0),+H46+H61+H76,0) -> -1416.3934 | I28: =IF(OR(I$12=Capital_Inputs!$F$18,I27<0),+I46+I61+I76,0) -> 0 | J28: =IF(OR(J$12=Capital_Inputs!$F$18,J27<0),+J46+J61+J76,0) -> 0 | K28: =IF(OR(K$12=Capital_Inputs!$F$18,K27<0),+K46+K61+K76,0) -> 0 | L28: =IF(OR(L$12=Capital_Inputs!$F$18,L27<0),+L46+L61+L76,0) -> -1416.3934 | ... X28: =IF(OR(X$12=Capital_Inputs!$F$18,X27<0),+X46+X61+X76,0) -> -22334.426
B29: Closing Balance | D29: =D22+D23+D28+D26 -> 28000 | E29: =E22+E23+E28+E26 -> 28000 | F29: =F22+F23+F28+F26 -> 28000 | G29: =G22+G23+G28+G26 -> 28000 | H29: =H22+H23+H28+H26 -> 26583.607 | I29: =I22+I23+I28+I26 -> 26583.607 | J29: =J22+J23+J28+J26 -> 26583.607 | K29: =K22+K23+K28+K26 -> 26583.607 | ... X29: =X22+X23+X28+X26 -> 7.2759576e-12
B31: Global Contractual IRR | C31: {=XIRR( _xlfn._xlws.FILTER(D31:X31,$D$11:$X$11<=Capital_Inputs!$F$19), _xlfn._xlws.FILTER(Debt_Model!$D$11:$X$11,Debt_Model!$D$11:$X$11<=Capital_Inputs!$F$19) )} -> 0.14917895 | D31: =-D23+D24 -> -27160 | E31: =+E25-E28-E23+E24 -> 930 | F31: =+F25-F28-F23+F24 -> 930 | G31: =+G25-G28-G23+G24 -> 930 | H31: =+H25-H28-H23+H24 -> 2346.3934 | I31: =+I25-I28-I23+I24 -> 893.70492 | J31: =+J25-J28-J23+J24 -> 893.70492 | K31: =+K25-K28-K23+K24 -> 893.70492 | L31: =+L25-L28-L23+L24 -> 2310.0984 | ... X31: =+X25-X28-X23+X24 -> 23119.246
B32: Global Contractual MoM | C32: =+SUM(E32:X32)/-D32 -> 1.6623047 | D32: =+D31 -> -27160 | E32: =+E31 -> 930 | F32: =+F31 -> 930 | G32: =+G31 -> 930 | H32: =+H31 -> 2346.3934 | I32: =+I31 -> 893.70492 | J32: =+J31 -> 893.70492 | K32: =+K31 -> 893.70492 | ... X32: =+X31 -> 23119.246
B34: Global Total IRR | C34: {=XIRR( _xlfn._xlws.FILTER(D34:X34,$D$11:$X$11<=Capital_Inputs!$F$19), _xlfn._xlws.FILTER(Debt_Model!$D$11:$X$11,Debt_Model!$D$11:$X$11<=Capital_Inputs!$F$19) )} -> 0.17984616 | D34: =D31+B89 -> -27159.9 | E34: =+E31+IF(E12=Capital_Inputs!$F$18,E92,0) -> 930 | F34: =+F31+IF(F12=Capital_Inputs!$F$18,F92,0) -> 930 | G34: =+G31+IF(G12=Capital_Inputs!$F$18,G92,0) -> 930 | H34: =+H31+IF(H12=Capital_Inputs!$F$18,H92,0) -> 2346.3934 | I34: =+I31+IF(I12=Capital_Inputs!$F$18,I92,0) -> 893.70492 | J34: =+J31+IF(J12=Capital_Inputs!$F$18,J92,0) -> 893.70492 | K34: =+K31+IF(K12=Capital_Inputs!$F$18,K92,0) -> 893.70492 | L34: =+L31+IF(L12=Capital_Inputs!$F$18,L92,0) -> 2310.0984 | ... X34: =+X31+IF(X12=Capital_Inputs!$F$18,X92,0) -> 28551.99
B35: Global Total MoM | C35: =+SUM(E35:X35)/-D35 -> 1.862339 | D35: =+D34 -> -27159.9 | E35: =+E34 -> 930 | F35: =+F34 -> 930 | G35: =+G34 -> 930 | H35: =+H34 -> 2346.3934 | I35: =+I34 -> 893.70492 | J35: =+J34 -> 893.70492 | K35: =+K34 -> 893.70492 | ... X35: =+X34 -> 28551.99
B37: =+Capital_Inputs!F23 -> Unitranche
B38: Opening Balance | D38: 0 | E38: =D47 -> 18000 | F38: =E47 -> 18000 | G38: =F47 -> 18000 | H38: =G47 -> 18000 | I38: =H47 -> 16583.607 | J38: =I47 -> 16583.607 | K38: =J47 -> 16583.607 | L38: =K47 -> 16583.607 | ... X38: =W47 -> 12334.426
B39: Advances | D39: =+Capital_Inputs!F44*1000 -> 18000
B40: Arranging Fee | C40: =+Capital_Inputs!F46 -> 0.03 | D40: =D39*C40 -> 540
B41: Interest Cash Paid | C41: =+Capital_Inputs!F47 -> 0.065 | E41: =IF($C41=0,0,E38*(0.25*($C41+E$8))) -> 461.25 | F41: =IF($C41=0,0,F38*(0.25*($C41+F$8))) -> 461.25 | G41: =IF($C41=0,0,G38*(0.25*($C41+G$8))) -> 461.25 | H41: =IF($C41=0,0,H38*(0.25*($C41+H$8))) -> 461.25 | I41: =IF($C41=0,0,I38*(0.25*($C41+I$8))) -> 424.95492 | J41: =IF($C41=0,0,J38*(0.25*($C41+J$8))) -> 424.95492 | K41: =IF($C41=0,0,K38*(0.25*($C41+K$8))) -> 424.95492 | L41: =IF($C41=0,0,L38*(0.25*($C41+L$8))) -> 424.95492 | ... X41: =IF($C41=0,0,X38*(0.25*($C41+X$8))) -> 316.06967
B42: Interest PIK | C42: =+Capital_Inputs!F48 -> 0 | E42: =E$38*($C42*0.25) -> 0 | F42: =F$38*($C42*0.25) -> 0 | G42: =G$38*($C42*0.25) -> 0 | H42: =H$38*($C42*0.25) -> 0 | I42: =I$38*($C42*0.25) -> 0 | J42: =J$38*($C42*0.25) -> 0 | K42: =K$38*($C42*0.25) -> 0 | L42: =L$38*($C42*0.25) -> 0 | ... X42: =X$38*($C42*0.25) -> 0
B43: Amortisation | C43: =+Capital_Inputs!F49 -> 0.4 | H43: =IF(AND(H38>0,$C44=FALSE),-($C43*$D39)/Capital_Inputs!$F$20,0) -> -1416.3934 | L43: =IF(AND(L38>0,$C44=FALSE),-($C43*$D39)/Capital_Inputs!$F$20,0) -> -1416.3934 | P43: =IF(AND(P38>0,$C44=FALSE),-($C43*$D39)/Capital_Inputs!$F$20,0) -> -1416.3934 | T43: =IF(AND(T38>0,$C44=FALSE),-($C43*$D39)/Capital_Inputs!$F$20,0) -> -1416.3934 | X43: =IF(AND(X38>0,$C44=FALSE),-($C43*$D39)/Capital_Inputs!$F$20,0) -> -1416.3934
B44: Sculpted | C44: FALSE
B45: Other mechanism
B46: Repayments | E46: =IF(Debt_Model!E$12=Capital_Inputs!$F$18,-E38-E42,IF(SUM(E43:E45)<0,SUM(E43:E45),0)) -> 0 | F46: =IF(Debt_Model!F$12=Capital_Inputs!$F$18,-F38-F42,IF(SUM(F43:F45)<0,SUM(F43:F45),0)) -> 0 | G46: =IF(Debt_Model!G$12=Capital_Inputs!$F$18,-G38-G42,IF(SUM(G43:G45)<0,SUM(G43:G45),0)) -> 0 | H46: =IF(Debt_Model!H$12=Capital_Inputs!$F$18,-H38-H42,IF(SUM(H43:H45)<0,SUM(H43:H45),0)) -> -1416.3934 | I46: =IF(Debt_Model!I$12=Capital_Inputs!$F$18,-I38-I42,IF(SUM(I43:I45)<0,SUM(I43:I45),0)) -> 0 | J46: =IF(Debt_Model!J$12=Capital_Inputs!$F$18,-J38-J42,IF(SUM(J43:J45)<0,SUM(J43:J45),0)) -> 0 | K46: =IF(Debt_Model!K$12=Capital_Inputs!$F$18,-K38-K42,IF(SUM(K43:K45)<0,SUM(K43:K45),0)) -> 0 | L46: =IF(Debt_Model!L$12=Capital_Inputs!$F$18,-L38-L42,IF(SUM(L43:L45)<0,SUM(L43:L45),0)) -> -1416.3934 | ... X46: =IF(Debt_Model!X$12=Capital_Inputs!$F$18,-X38-X42,IF(SUM(X43:X45)<0,SUM(X43:X45),0)) -> -12334.426
B47: Closing Balance | D47: =D38+D39-D46 -> 18000 | E47: =E38+E39+E46+E42 -> 18000 | F47: =F38+F39+F46+F42 -> 18000 | G47: =G38+G39+G46+G42 -> 18000 | H47: =H38+H39+H46+H42 -> 16583.607 | I47: =I38+I39+I46+I42 -> 16583.607 | J47: =J38+J39+J46+J42 -> 16583.607 | K47: =K38+K39+K46+K42 -> 16583.607 | L47: =L38+L39+L46+L42 -> 15167.213 | ... X47: =X38+X39+X46+X42 -> 0
B49: =B37& " Gross IRR" -> Unitranche Gross IRR | C49: {=XIRR( _xlfn._xlws.FILTER(D49:X49,$D$11:$X$11<=Capital_Inputs!$F$19), _xlfn._xlws.FILTER(Debt_Model!$D$11:$X$11,Debt_Model!$D$11:$X$11<=Capital_Inputs!$F$19) )} -> 0.12804263 | D49: =-D39+D40 -> -17460 | E49: =E41-E46 -> 461.25 | F49: =F41-F46 -> 461.25 | G49: =G41-G46 -> 461.25 | H49: =H41-H46 -> 1877.6434 | I49: =I41-I46 -> 424.95492 | J49: =J41-J46 -> 424.95492 | K49: =K41-K46 -> 424.95492 | L49: =L41-L46 -> 1841.3484 | ... W49: =W41-W46 -> 316.06967 | X49: =X41-X46-SUM(X43:X44) -> 14066.889
B50: =$B$37& " Gross MoM" -> Unitranche Gross MoM | C50: =+SUM(E50:X50)/-D50 -> 1.5572503 | D50: =+D49 -> -17460 | E50: =+E49 -> 461.25 | F50: =+F49 -> 461.25 | G50: =+G49 -> 461.25 | H50: =+H49 -> 1877.6434 | I50: =+I49 -> 424.95492 | J50: =+J49 -> 424.95492 | K50: =+K49 -> 424.95492 | ... X50: =+X49 -> 14066.889
...

Sheet Capital_Inputs
A1: x | I1: x
B2: =+D7 -> Project X
B3: {=MID(CELL("filename",A1),FIND("]",CELL("filename",A1))+1,255)} -> Capital_Inputs
B4: =F11& ", unless stated otherwise" -> £000's, unless stated otherwise
D7: Project X
C9: Static Assumptions
D11: Units | E11: £ | F11: £000's
D13: Entry Assumptions:
D14: Entry date: | E14: DMY | F14: =+TODAY() -> 46143
D16: Exit Assumptions:
D17: Investment term | E17: m | F17: 60
D18: Investment exit quarter | E18: m | F18: =MROUND(F17,3) -> 60
D19: Exit date: | E19: DMY | F19: =+EOMONTH(F14,F18) -> 47999
D20: Investment term | E20: y | F20: =YEARFRAC(F14,F19) -> 5.0833333
D22: Structure:
D23: Tranche 1: | F23: Unitranche
D24: Tranche 2: | F24: Preferred Equity
D25: Tranche 3:
D27: Structuring:
D28: Structuring EBITDA | E28: £000's | F28: 7250
D29: Structuring CFADS | E29: £000's | F29: 6981
D31: EV Multiples:
D32: Entry Multiple | E32: x | F32: 6
D33: Exit Multiple | E33: x | F33: 6
C35: Case assumptions
D37: P&L assumptions:
D38: EBITDA CAGR | E38: % | F38: 0.12
D39: CFADS | E39: % | F39: 0.7
C41: Debt Funding
D43: =+F23 & ":" -> Unitranche:
D44: Quantum | E44: £'m | F44: 18
D45: Implied Gross Leverage | E45: x | F45: =+F44/(Debt_Model!$D$10/1000) -> 2.4827586
D46: Arrangement Fee | E46: % | F46: 0.03
D47: Cash Margin | E47: % | F47: 0.065
D48: PIK Margin | E48: % | F48: 0
D49: Amortisation | E49: % | F49: 0.4
D50: Amortisation | E50: £'m | F50: =+F49*F44 -> 7.2
D51: Warrant | E51: % | F51: 0.1
D53: =+F24& ":" -> Preferred Equity:
D54: Max quantum | E54: £'m | F54: 10
...

Sheet Output
A1: x | J1: x
B2: =Capital_Inputs!D7 -> Project X
B3: {=MID(CELL("filename",A1),FIND("]",CELL("filename",A1))+1,255)} -> Output
B4: =+Capital_Inputs!F11 & ", unless stated otherwise" -> £000's, unless stated otherwise
B7: Returns attribution | F7: IRR | H7: MoM
B9: WDO Gross | F9: % | G9: =+Debt_Model!C130 -> 0.33679906 | H9: x | I9: =+Debt_Model!C131 -> 2.9170919
B10: WDO Net | F10: % | G10: =+Debt_Model!C133 -> 0.31972077 | H10: x | I10: =+Debt_Model!C134 -> 2.8535607
B11: Contractual | F11: % | G11: =+Debt_Model!C196 -> 0.26911617 | H11: x | I11: {=+SUM(Debt_Model!E196:X196/-Debt_Model!D196)} -> 2.2809393
B12: Amortisation | F12: % | G12: =+Debt_Model!C203 -> 0
B13: Interest - PIK | F13: % | G13: =+Debt_Model!C201 -> 0
B14: Interest - Cash | F14: % | G14: =+Debt_Model!C197 -> 0.24802756
B15: Arrangement Fee | F15: % | G15: =+Debt_Model!C199 -> 0.021088612
B16: Equity / Warrant | F16: % | G16: =+Debt_Model!C205 -> 0.067682886
B17: RMB | F17: % | G17: =+Debt_Model!C136 -> 0.0890389 | H17: x | I17: =+Debt_Model!C137 -> 1.3785701
B19: Dashboard | D19: =+EOMONTH(Capital_Inputs!F14,-12) -> 45808 | E19: =+Capital_Inputs!F14 -> 46143 | F19: =+EOMONTH(E19,12) -> 46538 | G19: =+EOMONTH(F19,12) -> 46904 | H19: =+EOMONTH(G19,12) -> 47269 | I19: =+EOMONTH(H19,12) -> 47634
B21: EBITDA | D21: =+Debt_Model!D10 -> 7250 | E21: =+Debt_Model!H10 -> 8120 | F21: =+Debt_Model!L10 -> 9094.4 | G21: =+Debt_Model!P10 -> 10185.728 | H21: =+Debt_Model!T10 -> 11408.015 | I21: =+Debt_Model!X10 -> 12776.977
B22: % Growth | E22: =E21/D21-1 -> 0.12 | F22: =F21/E21-1 -> 0.12 | G22: =G21/F21-1 -> 0.12 | H22: =H21/G21-1 -> 0.12 | I22: =I21/H21-1 -> 0.12
B24: CFADS | D24: =+Capital_Inputs!F29 -> 6981 | E24: =+E21*Capital_Inputs!$F$39 -> 5684 | F24: =+F21*Capital_Inputs!$F$39 -> 6366.08 | G24: =+G21*Capital_Inputs!$F$39 -> 7130.0096 | H24: =+H21*Capital_Inputs!$F$39 -> 7985.6108 | I24: =+I21*Capital_Inputs!$F$39 -> 8943.884
B25: % GM | D25: =+D24/D$21 -> 0.96289655 | E25: =+E24/E$21 -> 0.7 | F25: =+F24/F$21 -> 0.7 | G25: =+G24/G$21 -> 0.7 | H25: =+H24/H$21 -> 0.7 | I25: =+I24/I$21 -> 0.7
B27: Debt Service | E27: =-SUM(Debt_Model!E25:H25)+Debt_Model!H27 -> -5136.3934 | F27: =-SUM(Debt_Model!I25:L25)+Debt_Model!L27 -> -4991.2131 | G27: =-SUM(Debt_Model!M25:P25)+Debt_Model!P27 -> -4846.0328 | H27: =-SUM(Debt_Model!Q25:T25)+Debt_Model!T27 -> -4700.8525 | I27: =-SUM(Debt_Model!U25:X25)+Debt_Model!X27 -> -4555.6721
B29: Net Cash | E29: =+E27+E24 -> 547.60656 | F29: =+F27+F24 -> 1374.8669 | G29: =+G27+G24 -> 2283.9768 | H29: =+H27+H24 -> 3284.7583 | I29: =+I27+I24 -> 4388.2119
B31: KPIs
B33: Senior Facility xEBITDA | D33: =+Debt_Model!$D$47/Output!D21 -> 2.4827586 | E33: =+Debt_Model!$H$47/Output!E21 -> 2.0423161 | F33: =+Debt_Model!$L$47/Output!F21 -> 1.667753 | G33: =+Debt_Model!$P$47/Output!G21 -> 1.3500085 | H33: =+Debt_Model!$T$47/Output!H21 -> 1.081207 | I33: =-Debt_Model!$X$46/Output!I21 -> 0.96536341
B34: Global Facility xEBITDA | D34: =+Debt_Model!$D$29/D21 -> 3.862069 | E34: =+Debt_Model!$H$29/E21 -> 3.2738432 | F34: =+Debt_Model!$L$29/F21 -> 2.7673308 | G34: =+Debt_Model!$P$29/G21 -> 2.3317744 | H34: =+Debt_Model!$T$29/H21 -> 1.9577837 | I34: =+Debt_Model!$X$28/-I21 -> 1.7480211
B35: Senior Facility xCFADS | D35: =+Debt_Model!$D$47/D24 -> 2.5784272 | E35: =+Debt_Model!$H$47/E24 -> 2.9175944 | F35: =+Debt_Model!$H$47/F24 -> 2.604995 | G35: =+Debt_Model!$H$47/G24 -> 2.3258884 | H35: =+Debt_Model!$H$47/H24 -> 2.0766861 | I35: =+Debt_Model!$H$47/I24 -> 1.854184
B36: Global Facility xCFADS | D36: =+Debt_Model!$D$29/D24 -> 4.0108867 | E36: =+Debt_Model!$H$29/E24 -> 4.6769188 | F36: =+Debt_Model!$H$29/F24 -> 4.1758204 | G36: =+Debt_Model!$H$29/G24 -> 3.728411 | H36: =+Debt_Model!$H$29/H24 -> 3.3289384 | I36: =+Debt_Model!$H$29/I24 -> 2.9722665
B37: DSCR | E37: =-E24/E27 -> 1.106613 | F37: =-F24/F27 -> 1.2754575 | G37: =-G24/G27 -> 1.4713086 | H37: =-H24/H27 -> 1.698758 | I37: =-I24/I27 -> 1.9632414
A39: x | J39: x
